Workbook

Sheet Dashboard
A1: VG SUPPORT | TEAM KPI DASHBOARD | R1: Priority | S1: Ticket Count | U1: Status | V1: Ticket Count | X1: Handler | Y1: Ticket Count | AA1: Month | AB1: All Tickets | AC1: P1 Tickets | AD1: SLA Breaches | AE1: SLA Compliance
R2: P1 | S2: =COUNTIFS(Data!$D$2:$D$1000,R2,Data!$B$2:$B$1000,">="&$B$4,Data!$B$2:$B$1000,"<="&$D$4) -> 17 | U2: Closed | V2: =COUNTIFS(Data!$E$2:$E$1000,U2,Data!$B$2:$B$1000,">="&$B$4,Data!$B$2:$B$1000,"<="&$D$4) -> 29 | X2: A. Sharma | Y2: =COUNTIFS(Data!$G$2:$G$1000,X2,Data!$B$2:$B$1000,">="&$B$4,Data!$B$2:$B$1000,"<="&$D$4) -> 11 | AA2: 46023 | AB2: =COUNTIFS(Data!$B$2:$B$1000,">="&MAX($AA2,$B$4),Data!$B$2:$B$1000,"<"&MIN(DATE(YEAR($AA2),MONTH($AA2)+1,1),$D$4+1)) -> 0 | AC2: =COUNTIFS(Data!$D$2:$D$1000,"P1",Data!$B$2:$B$1000,">="&MAX($AA2,$B$4),Data!$B$2:$B$1000,"<"&MIN(DATE(YEAR($AA2),MONTH($AA2)+1,1),$D$4+1)) -> 0 | AD2: =COUNTIFS(Data!$J$2:$J$1000,"No",Data!$B$2:$B$1000,">="&MAX($AA2,$B$4),Data!$B$2:$B$1000,"<"&MIN(DATE(YEAR($AA2),MONTH($AA2)+1,1),$D$4+1)) -> 0 | AE2: =IFERROR(COUNTIFS(Data!$B$2:$B$1000,">="&MAX($AA2,$B$4),Data!$B$2:$B$1000,"<"&MIN(DATE(YEAR($AA2),MONTH($AA2)+1,1),$D$4+1),Data!$J$2:$J$1000,"Yes")/(COUNTIFS(Data!$B$2:$B$1000,">="&MAX($AA2,$B$4),Data!$B$2:$B$1000,"<"&MIN(DATE(YEAR($AA2),MONTH($AA2)+1,1),$D$4+1),Data!$J$2:$J$1000,"Yes")+COUNTIFS(Data!$B$2:$B$1000,">="&MAX($AA2,$B$4),Data!$B$2:$B$1000,"<"&MIN(DATE(YEAR($AA2),MONTH($AA2)+1,1),$D$4+1),Data!$J$2:$J$1000,"No")),0) -> 0
A3: Executive summary • Priority workload • SLA performance • Monthly trends | R3: P2 | S3: =COUNTIFS(Data!$D$2:$D$1000,R3,Data!$B$2:$B$1000,">="&$B$4,Data!$B$2:$B$1000,"<="&$D$4) -> 14 | U3: In Progress | V3: =COUNTIFS(Data!$E$2:$E$1000,U3,Data!$B$2:$B$1000,">="&$B$4,Data!$B$2:$B$1000,"<="&$D$4) -> 7 | X3: R. Patel | Y3: =COUNTIFS(Data!$G$2:$G$1000,X3,Data!$B$2:$B$1000,">="&$B$4,Data!$B$2:$B$1000,"<="&$D$4) -> 4 | AA3: 46054 | AB3: =COUNTIFS(Data!$B$2:$B$1000,">="&MAX($AA3,$B$4),Data!$B$2:$B$1000,"<"&MIN(DATE(YEAR($AA3),MONTH($AA3)+1,1),$D$4+1)) -> 0 | AC3: =COUNTIFS(Data!$D$2:$D$1000,"P1",Data!$B$2:$B$1000,">="&MAX($AA3,$B$4),Data!$B$2:$B$1000,"<"&MIN(DATE(YEAR($AA3),MONTH($AA3)+1,1),$D$4+1)) -> 0 | AD3: =COUNTIFS(Data!$J$2:$J$1000,"No",Data!$B$2:$B$1000,">="&MAX($AA3,$B$4),Data!$B$2:$B$1000,"<"&MIN(DATE(YEAR($AA3),MONTH($AA3)+1,1),$D$4+1)) -> 0 | AE3: =IFERROR(COUNTIFS(Data!$B$2:$B$1000,">="&MAX($AA3,$B$4),Data!$B$2:$B$1000,"<"&MIN(DATE(YEAR($AA3),MONTH($AA3)+1,1),$D$4+1),Data!$J$2:$J$1000,"Yes")/(COUNTIFS(Data!$B$2:$B$1000,">="&MAX($AA3,$B$4),Data!$B$2:$B$1000,"<"&MIN(DATE(YEAR($AA3),MONTH($AA3)+1,1),$D$4+1),Data!$J$2:$J$1000,"Yes")+COUNTIFS(Data!$B$2:$B$1000,">="&MAX($AA3,$B$4),Data!$B$2:$B$1000,"<"&MIN(DATE(YEAR($AA3),MONTH($AA3)+1,1),$D$4+1),Data!$J$2:$J$1000,"No")),0) -> 0
A4: Start date | B4: 46143 | C4: End date | D4: 46326 | F4: Change the yellow date cells to filter KPI cards and graphs. | R4: P3 | S4: =COUNTIFS(Data!$D$2:$D$1000,R4,Data!$B$2:$B$1000,">="&$B$4,Data!$B$2:$B$1000,"<="&$D$4) -> 10 | U4: Open | V4: =COUNTIFS(Data!$E$2:$E$1000,U4,Data!$B$2:$B$1000,">="&$B$4,Data!$B$2:$B$1000,"<="&$D$4) -> 5 | X4: S. Kumar | Y4: =COUNTIFS(Data!$G$2:$G$1000,X4,Data!$B$2:$B$1000,">="&$B$4,Data!$B$2:$B$1000,"<="&$D$4) -> 12 | AA4: 46082 | AB4: =COUNTIFS(Data!$B$2:$B$1000,">="&MAX($AA4,$B$4),Data!$B$2:$B$1000,"<"&MIN(DATE(YEAR($AA4),MONTH($AA4)+1,1),$D$4+1)) -> 0 | AC4: =COUNTIFS(Data!$D$2:$D$1000,"P1",Data!$B$2:$B$1000,">="&MAX($AA4,$B$4),Data!$B$2:$B$1000,"<"&MIN(DATE(YEAR($AA4),MONTH($AA4)+1,1),$D$4+1)) -> 0 | AD4: =COUNTIFS(Data!$J$2:$J$1000,"No",Data!$B$2:$B$1000,">="&MAX($AA4,$B$4),Data!$B$2:$B$1000,"<"&MIN(DATE(YEAR($AA4),MONTH($AA4)+1,1),$D$4+1)) -> 0 | AE4: =IFERROR(COUNTIFS(Data!$B$2:$B$1000,">="&MAX($AA4,$B$4),Data!$B$2:$B$1000,"<"&MIN(DATE(YEAR($AA4),MONTH($AA4)+1,1),$D$4+1),Data!$J$2:$J$1000,"Yes")/(COUNTIFS(Data!$B$2:$B$1000,">="&MAX($AA4,$B$4),Data!$B$2:$B$1000,"<"&MIN(DATE(YEAR($AA4),MONTH($AA4)+1,1),$D$4+1),Data!$J$2:$J$1000,"Yes")+COUNTIFS(Data!$B$2:$B$1000,">="&MAX($AA4,$B$4),Data!$B$2:$B$1000,"<"&MIN(DATE(YEAR($AA4),MONTH($AA4)+1,1),$D$4+1),Data!$J$2:$J$1000,"No")),0) -> 0
X5: M. Singh | Y5: =COUNTIFS(Data!$G$2:$G$1000,X5,Data!$B$2:$B$1000,">="&$B$4,Data!$B$2:$B$1000,"<="&$D$4) -> 6 | AA5: 46113 | AB5: =COUNTIFS(Data!$B$2:$B$1000,">="&MAX($AA5,$B$4),Data!$B$2:$B$1000,"<"&MIN(DATE(YEAR($AA5),MONTH($AA5)+1,1),$D$4+1)) -> 0 | AC5: =COUNTIFS(Data!$D$2:$D$1000,"P1",Data!$B$2:$B$1000,">="&MAX($AA5,$B$4),Data!$B$2:$B$1000,"<"&MIN(DATE(YEAR($AA5),MONTH($AA5)+1,1),$D$4+1)) -> 0 | AD5: =COUNTIFS(Data!$J$2:$J$1000,"No",Data!$B$2:$B$1000,">="&MAX($AA5,$B$4),Data!$B$2:$B$1000,"<"&MIN(DATE(YEAR($AA5),MONTH($AA5)+1,1),$D$4+1)) -> 0 | AE5: =IFERROR(COUNTIFS(Data!$B$2:$B$1000,">="&MAX($AA5,$B$4),Data!$B$2:$B$1000,"<"&MIN(DATE(YEAR($AA5),MONTH($AA5)+1,1),$D$4+1),Data!$J$2:$J$1000,"Yes")/(COUNTIFS(Data!$B$2:$B$1000,">="&MAX($AA5,$B$4),Data!$B$2:$B$1000,"<"&MIN(DATE(YEAR($AA5),MONTH($AA5)+1,1),$D$4+1),Data!$J$2:$J$1000,"Yes")+COUNTIFS(Data!$B$2:$B$1000,">="&MAX($AA5,$B$4),Data!$B$2:$B$1000,"<"&MIN(DATE(YEAR($AA5),MONTH($AA5)+1,1),$D$4+1),Data!$J$2:$J$1000,"No")),0) -> 0
A6: TOTAL TICKETS | D6: P1 TICKETS | G6: SLA BREACHES | J6: SLA COMPLIANCE | M6: OPEN / IN PROGRESS | X6: P. Joshi | Y6: =COUNTIFS(Data!$G$2:$G$1000,X6,Data!$B$2:$B$1000,">="&$B$4,Data!$B$2:$B$1000,"<="&$D$4) -> 8 | AA6: 46143 | AB6: =COUNTIFS(Data!$B$2:$B$1000,">="&MAX($AA6,$B$4),Data!$B$2:$B$1000,"<"&MIN(DATE(YEAR($AA6),MONTH($AA6)+1,1),$D$4+1)) -> 4 | AC6: =COUNTIFS(Data!$D$2:$D$1000,"P1",Data!$B$2:$B$1000,">="&MAX($AA6,$B$4),Data!$B$2:$B$1000,"<"&MIN(DATE(YEAR($AA6),MONTH($AA6)+1,1),$D$4+1)) -> 1 | AD6: =COUNTIFS(Data!$J$2:$J$1000,"No",Data!$B$2:$B$1000,">="&MAX($AA6,$B$4),Data!$B$2:$B$1000,"<"&MIN(DATE(YEAR($AA6),MONTH($AA6)+1,1),$D$4+1)) -> 2 | AE6: =IFERROR(COUNTIFS(Data!$B$2:$B$1000,">="&MAX($AA6,$B$4),Data!$B$2:$B$1000,"<"&MIN(DATE(YEAR($AA6),MONTH($AA6)+1,1),$D$4+1),Data!$J$2:$J$1000,"Yes")/(COUNTIFS(Data!$B$2:$B$1000,">="&MAX($AA6,$B$4),Data!$B$2:$B$1000,"<"&MIN(DATE(YEAR($AA6),MONTH($AA6)+1,1),$D$4+1),Data!$J$2:$J$1000,"Yes")+COUNTIFS(Data!$B$2:$B$1000,">="&MAX($AA6,$B$4),Data!$B$2:$B$1000,"<"&MIN(DATE(YEAR($AA6),MONTH($AA6)+1,1),$D$4+1),Data!$J$2:$J$1000,"No")),0) -> 0.33333333
A7: =COUNTIFS(Data!$B$2:$B$1000,">="&$B$4,Data!$B$2:$B$1000,"<="&$D$4) -> 41 | D7: =COUNTIFS(Data!$D$2:$D$1000,"P1",Data!$B$2:$B$1000,">="&$B$4,Data!$B$2:$B$1000,"<="&$D$4) -> 17 | G7: =COUNTIFS(Data!$J$2:$J$1000,"No",Data!$B$2:$B$1000,">="&$B$4,Data!$B$2:$B$1000,"<="&$D$4) -> 13 | J7: =IFERROR(COUNTIFS(Data!$J$2:$J$1000,"Yes",Data!$B$2:$B$1000,">="&$B$4,Data!$B$2:$B$1000,"<="&$D$4)/(COUNTIFS(Data!$J$2:$J$1000,"Yes",Data!$B$2:$B$1000,">="&$B$4,Data!$B$2:$B$1000,"<="&$D$4)+COUNTIFS(Data!$J$2:$J$1000,"No",Data!$B$2:$B$1000,">="&$B$4,Data!$B$2:$B$1000,"<="&$D$4)),0) -> 0.55172414 | M7: =COUNTIFS(Data!$E$2:$E$1000,"Open",Data!$B$2:$B$1000,">="&$B$4,Data!$B$2:$B$1000,"<="&$D$4,Data!$E$2:$E$1000,"Open")+COUNTIFS(Data!$B$2:$B$1000,">="&$B$4,Data!$B$2:$B$1000,"<="&$D$4,Data!$E$2:$E$1000,"In Progress") -> 12 | AA7: 46174 | AB7: =COUNTIFS(Data!$B$2:$B$1000,">="&MAX($AA7,$B$4),Data!$B$2:$B$1000,"<"&MIN(DATE(YEAR($AA7),MONTH($AA7)+1,1),$D$4+1)) -> 10 | AC7: =COUNTIFS(Data!$D$2:$D$1000,"P1",Data!$B$2:$B$1000,">="&MAX($AA7,$B$4),Data!$B$2:$B$1000,"<"&MIN(DATE(YEAR($AA7),MONTH($AA7)+1,1),$D$4+1)) -> 4 | AD7: =COUNTIFS(Data!$J$2:$J$1000,"No",Data!$B$2:$B$1000,">="&MAX($AA7,$B$4),Data!$B$2:$B$1000,"<"&MIN(DATE(YEAR($AA7),MONTH($AA7)+1,1),$D$4+1)) -> 3 | AE7: =IFERROR(COUNTIFS(Data!$B$2:$B$1000,">="&MAX($AA7,$B$4),Data!$B$2:$B$1000,"<"&MIN(DATE(YEAR($AA7),MONTH($AA7)+1,1),$D$4+1),Data!$J$2:$J$1000,"Yes")/(COUNTIFS(Data!$B$2:$B$1000,">="&MAX($AA7,$B$4),Data!$B$2:$B$1000,"<"&MIN(DATE(YEAR($AA7),MONTH($AA7)+1,1),$D$4+1),Data!$J$2:$J$1000,"Yes")+COUNTIFS(Data!$B$2:$B$1000,">="&MAX($AA7,$B$4),Data!$B$2:$B$1000,"<"&MIN(DATE(YEAR($AA7),MONTH($AA7)+1,1),$D$4+1),Data!$J$2:$J$1000,"No")),0) -> 0.57142857
AA8: 46204 | AB8: =COUNTIFS(Data!$B$2:$B$1000,">="&MAX($AA8,$B$4),Data!$B$2:$B$1000,"<"&MIN(DATE(YEAR($AA8),MONTH($AA8)+1,1),$D$4+1)) -> 10 | AC8: =COUNTIFS(Data!$D$2:$D$1000,"P1",Data!$B$2:$B$1000,">="&MAX($AA8,$B$4),Data!$B$2:$B$1000,"<"&MIN(DATE(YEAR($AA8),MONTH($AA8)+1,1),$D$4+1)) -> 4 | AD8: =COUNTIFS(Data!$J$2:$J$1000,"No",Data!$B$2:$B$1000,">="&MAX($AA8,$B$4),Data!$B$2:$B$1000,"<"&MIN(DATE(YEAR($AA8),MONTH($AA8)+1,1),$D$4+1)) -> 4 | AE8: =IFERROR(COUNTIFS(Data!$B$2:$B$1000,">="&MAX($AA8,$B$4),Data!$B$2:$B$1000,"<"&MIN(DATE(YEAR($AA8),MONTH($AA8)+1,1),$D$4+1),Data!$J$2:$J$1000,"Yes")/(COUNTIFS(Data!$B$2:$B$1000,">="&MAX($AA8,$B$4),Data!$B$2:$B$1000,"<"&MIN(DATE(YEAR($AA8),MONTH($AA8)+1,1),$D$4+1),Data!$J$2:$J$1000,"Yes")+COUNTIFS(Data!$B$2:$B$1000,">="&MAX($AA8,$B$4),Data!$B$2:$B$1000,"<"&MIN(DATE(YEAR($AA8),MONTH($AA8)+1,1),$D$4+1),Data!$J$2:$J$1000,"No")),0) -> 0.5
AA9: 46235 | AB9: =COUNTIFS(Data!$B$2:$B$1000,">="&MAX($AA9,$B$4),Data!$B$2:$B$1000,"<"&MIN(DATE(YEAR($AA9),MONTH($AA9)+1,1),$D$4+1)) -> 11 | AC9: =COUNTIFS(Data!$D$2:$D$1000,"P1",Data!$B$2:$B$1000,">="&MAX($AA9,$B$4),Data!$B$2:$B$1000,"<"&MIN(DATE(YEAR($AA9),MONTH($AA9)+1,1),$D$4+1)) -> 5 | AD9: =COUNTIFS(Data!$J$2:$J$1000,"No",Data!$B$2:$B$1000,">="&MAX($AA9,$B$4),Data!$B$2:$B$1000,"<"&MIN(DATE(YEAR($AA9),MONTH($AA9)+1,1),$D$4+1)) -> 2 | AE9: =IFERROR(COUNTIFS(Data!$B$2:$B$1000,">="&MAX($AA9,$B$4),Data!$B$2:$B$1000,"<"&MIN(DATE(YEAR($AA9),MONTH($AA9)+1,1),$D$4+1),Data!$J$2:$J$1000,"Yes")/(COUNTIFS(Data!$B$2:$B$1000,">="&MAX($AA9,$B$4),Data!$B$2:$B$1000,"<"&MIN(DATE(YEAR($AA9),MONTH($AA9)+1,1),$D$4+1),Data!$J$2:$J$1000,"Yes")+COUNTIFS(Data!$B$2:$B$1000,">="&MAX($AA9,$B$4),Data!$B$2:$B$1000,"<"&MIN(DATE(YEAR($AA9),MONTH($AA9)+1,1),$D$4+1),Data!$J$2:$J$1000,"No")),0) -> 0.6
AA10: 46266 | AB10: =COUNTIFS(Data!$B$2:$B$1000,">="&MAX($AA10,$B$4),Data!$B$2:$B$1000,"<"&MIN(DATE(YEAR($AA10),MONTH($AA10)+1,1),$D$4+1)) -> 2 | AC10: =COUNTIFS(Data!$D$2:$D$1000,"P1",Data!$B$2:$B$1000,">="&MAX($AA10,$B$4),Data!$B$2:$B$1000,"<"&MIN(DATE(YEAR($AA10),MONTH($AA10)+1,1),$D$4+1)) -> 1 | AD10: =COUNTIFS(Data!$J$2:$J$1000,"No",Data!$B$2:$B$1000,">="&MAX($AA10,$B$4),Data!$B$2:$B$1000,"<"&MIN(DATE(YEAR($AA10),MONTH($AA10)+1,1),$D$4+1)) -> 1 | AE10: =IFERROR(COUNTIFS(Data!$B$2:$B$1000,">="&MAX($AA10,$B$4),Data!$B$2:$B$1000,"<"&MIN(DATE(YEAR($AA10),MONTH($AA10)+1,1),$D$4+1),Data!$J$2:$J$1000,"Yes")/(COUNTIFS(Data!$B$2:$B$1000,">="&MAX($AA10,$B$4),Data!$B$2:$B$1000,"<"&MIN(DATE(YEAR($AA10),MONTH($AA10)+1,1),$D$4+1),Data!$J$2:$J$1000,"Yes")+COUNTIFS(Data!$B$2:$B$1000,">="&MAX($AA10,$B$4),Data!$B$2:$B$1000,"<"&MIN(DATE(YEAR($AA10),MONTH($AA10)+1,1),$D$4+1),Data!$J$2:$J$1000,"No")),0) -> 0.5
A11: SECTION 1 | PRIORITY & STATUS OVERVIEW | AA11: 46296 | AB11: =COUNTIFS(Data!$B$2:$B$1000,">="&MAX($AA11,$B$4),Data!$B$2:$B$1000,"<"&MIN(DATE(YEAR($AA11),MONTH($AA11)+1,1),$D$4+1)) -> 4 | AC11: =COUNTIFS(Data!$D$2:$D$1000,"P1",Data!$B$2:$B$1000,">="&MAX($AA11,$B$4),Data!$B$2:$B$1000,"<"&MIN(DATE(YEAR($AA11),MONTH($AA11)+1,1),$D$4+1)) -> 2 | AD11: =COUNTIFS(Data!$J$2:$J$1000,"No",Data!$B$2:$B$1000,">="&MAX($AA11,$B$4),Data!$B$2:$B$1000,"<"&MIN(DATE(YEAR($AA11),MONTH($AA11)+1,1),$D$4+1)) -> 1 | AE11: =IFERROR(COUNTIFS(Data!$B$2:$B$1000,">="&MAX($AA11,$B$4),Data!$B$2:$B$1000,"<"&MIN(DATE(YEAR($AA11),MONTH($AA11)+1,1),$D$4+1),Data!$J$2:$J$1000,"Yes")/(COUNTIFS(Data!$B$2:$B$1000,">="&MAX($AA11,$B$4),Data!$B$2:$B$1000,"<"&MIN(DATE(YEAR($AA11),MONTH($AA11)+1,1),$D$4+1),Data!$J$2:$J$1000,"Yes")+COUNTIFS(Data!$B$2:$B$1000,">="&MAX($AA11,$B$4),Data!$B$2:$B$1000,"<"&MIN(DATE(YEAR($AA11),MONTH($AA11)+1,1),$D$4+1),Data!$J$2:$J$1000,"No")),0) -> 0.75
AA12: 46327 | AB12: =COUNTIFS(Data!$B$2:$B$1000,">="&MAX($AA12,$B$4),Data!$B$2:$B$1000,"<"&MIN(DATE(YEAR($AA12),MONTH($AA12)+1,1),$D$4+1)) -> 0 | AC12: =COUNTIFS(Data!$D$2:$D$1000,"P1",Data!$B$2:$B$1000,">="&MAX($AA12,$B$4),Data!$B$2:$B$1000,"<"&MIN(DATE(YEAR($AA12),MONTH($AA12)+1,1),$D$4+1)) -> 0 | AD12: =COUNTIFS(Data!$J$2:$J$1000,"No",Data!$B$2:$B$1000,">="&MAX($AA12,$B$4),Data!$B$2:$B$1000,"<"&MIN(DATE(YEAR($AA12),MONTH($AA12)+1,1),$D$4+1)) -> 0 | AE12: =IFERROR(COUNTIFS(Data!$B$2:$B$1000,">="&MAX($AA12,$B$4),Data!$B$2:$B$1000,"<"&MIN(DATE(YEAR($AA12),MONTH($AA12)+1,1),$D$4+1),Data!$J$2:$J$1000,"Yes")/(COUNTIFS(Data!$B$2:$B$1000,">="&MAX($AA12,$B$4),Data!$B$2:$B$1000,"<"&MIN(DATE(YEAR($AA12),MONTH($AA12)+1,1),$D$4+1),Data!$J$2:$J$1000,"Yes")+COUNTIFS(Data!$B$2:$B$1000,">="&MAX($AA12,$B$4),Data!$B$2:$B$1000,"<"&MIN(DATE(YEAR($AA12),MONTH($AA12)+1,1),$D$4+1),Data!$J$2:$J$1000,"No")),0) -> 0
AA13: 46357 | AB13: =COUNTIFS(Data!$B$2:$B$1000,">="&MAX($AA13,$B$4),Data!$B$2:$B$1000,"<"&MIN(DATE(YEAR($AA13),MONTH($AA13)+1,1),$D$4+1)) -> 0 | AC13: =COUNTIFS(Data!$D$2:$D$1000,"P1",Data!$B$2:$B$1000,">="&MAX($AA13,$B$4),Data!$B$2:$B$1000,"<"&MIN(DATE(YEAR($AA13),MONTH($AA13)+1,1),$D$4+1)) -> 0 | AD13: =COUNTIFS(Data!$J$2:$J$1000,"No",Data!$B$2:$B$1000,">="&MAX($AA13,$B$4),Data!$B$2:$B$1000,"<"&MIN(DATE(YEAR($AA13),MONTH($AA13)+1,1),$D$4+1)) -> 0 | AE13: =IFERROR(COUNTIFS(Data!$B$2:$B$1000,">="&MAX($AA13,$B$4),Data!$B$2:$B$1000,"<"&MIN(DATE(YEAR($AA13),MONTH($AA13)+1,1),$D$4+1),Data!$J$2:$J$1000,"Yes")/(COUNTIFS(Data!$B$2:$B$1000,">="&MAX($AA13,$B$4),Data!$B$2:$B$1000,"<"&MIN(DATE(YEAR($AA13),MONTH($AA13)+1,1),$D$4+1),Data!$J$2:$J$1000,"Yes")+COUNTIFS(Data!$B$2:$B$1000,">="&MAX($AA13,$B$4),Data!$B$2:$B$1000,"<"&MIN(DATE(YEAR($AA13),MONTH($AA13)+1,1),$D$4+1),Data!$J$2:$J$1000,"No")),0) -> 0
A27: SECTION 2 | TEAM WORKLOAD
A43: SECTION 3 | MONTHLY TRENDS
A60: SECTION 4 | SLA TRENDS
A77: SECTION 5 | MONTHLY METRICS TABLE
A78: Month | B78: All Tickets | C78: P1 Tickets | D78: SLA Breaches | E78: SLA Compliance
A79: =AA2 -> 46023 | B79: =AB2 -> 0 | C79: =AC2 -> 0 | D79: =AD2 -> 0 | E79: =AE2 -> 0
A80: =AA3 -> 46054 | B80: =AB3 -> 0 | C80: =AC3 -> 0 | D80: =AD3 -> 0 | E80: =AE3 -> 0
A81: =AA4 -> 46082 | B81: =AB4 -> 0 | C81: =AC4 -> 0 | D81: =AD4 -> 0 | E81: =AE4 -> 0
A82: =AA5 -> 46113 | B82: =AB5 -> 0 | C82: =AC5 -> 0 | D82: =AD5 -> 0 | E82: =AE5 -> 0
A83: =AA6 -> 46143 | B83: =AB6 -> 4 | C83: =AC6 -> 1 | D83: =AD6 -> 2 | E83: =AE6 -> 0.33333333
A84: =AA7 -> 46174 | B84: =AB7 -> 10 | C84: =AC7 -> 4 | D84: =AD7 -> 3 | E84: =AE7 -> 0.57142857
A85: =AA8 -> 46204 | B85: =AB8 -> 10 | C85: =AC8 -> 4 | D85: =AD8 -> 4 | E85: =AE8 -> 0.5
A86: =AA9 -> 46235 | B86: =AB9 -> 11 | C86: =AC9 -> 5 | D86: =AD9 -> 2 | E86: =AE9 -> 0.6
A87: =AA10 -> 46266 | B87: =AB10 -> 2 | C87: =AC10 -> 1 | D87: =AD10 -> 1 | E87: =AE10 -> 0.5
A88: =AA11 -> 46296 | B88: =AB11 -> 4 | C88: =AC11 -> 2 | D88: =AD11 -> 1 | E88: =AE11 -> 0.75
A89: =AA12 -> 46327 | B89: =AB12 -> 0 | C89: =AC12 -> 0 | D89: =AD12 -> 0 | E89: =AE12 -> 0
A90: =AA13 -> 46357 | B90: =AB13 -> 0 | C90: =AC13 -> 0 | D90: =AD13 -> 0 | E90: =AE13 -> 0
A94: SECTION 6 | THIS MONTHS TICKETS
A95: Ticket ID | B95: Created Date | C95: Priority | D95: Status | E95: Category | F95: Assigned To | G95: SLA Target (hrs) | H95: Resolution Time (hrs) | I95: SLA Met | J95: Channel
A96: =Data!A2 -> VG-1001 | B96: =Data!B2 -> 46077 | C96: =Data!D2 -> P3 | D96: =Data!E2 -> Closed | E96: =Data!F2 -> Application Error | F96: =Data!G2 -> S. Kumar | G96: =Data!H2 -> 24 | H96: =Data!I2 -> 25.4 | I96: =Data!J2 -> No | J96: =Data!K2 -> Phone
A97: =Data!A3 -> VG-1002 | B97: =Data!B3 -> 46153 | C97: =Data!D3 -> P2 | D97: =Data!E3 -> Closed | E97: =Data!F3 -> Performance | F97: =Data!G3 -> M. Singh | G97: =Data!H3 -> 8 | H97: =Data!I3 -> 8.8 | I97: =Data!J3 -> No | J97: =Data!K3 -> Phone
A98: =Data!A4 -> VG-1003 | B98: =Data!B4 -> 46226 | C98: =Data!D4 -> P2 | D98: =Data!E4 -> In Progress | E98: =Data!F4 -> Access | F98: =Data!G4 -> S. Kumar | G98: =Data!H4 -> 8 | H98: =Data!I4 -> 0 | I98: =Data!J4 -> Pending | J98: =Data!K4 -> Email
A99: =Data!A5 -> VG-1004 | B99: =Data!B5 -> 46184 | C99: =Data!D5 -> P2 | D99: =Data!E5 -> In Progress | E99: =Data!F5 -> Performance | F99: =Data!G5 -> P. Joshi | G99: =Data!H5 -> 8 | H99: =Data!I5 -> 0 | I99: =Data!J5 -> Pending | J99: =Data!K5 -> Email
A100: =Data!A6 -> VG-1005 | B100: =Data!B6 -> 46105 | C100: =Data!D6 -> P3 | D100: =Data!E6 -> Closed | E100: =Data!F6 -> Access | F100: =Data!G6 -> A. Sharma | G100: =Data!H6 -> 24 | H100: =Data!I6 -> 11.3 | I100: =Data!J6 -> Yes | J100: =Data!K6 -> Email
A101: =Data!A7 -> VG-1006 | B101: =Data!B7 -> 46195 | C101: =Data!D7 -> P1 | D101: =Data!E7 -> Closed | E101: =Data!F7 -> Service Request | F101: =Data!G7 -> M. Singh | G101: =Data!H7 -> 4 | H101: =Data!I7 -> 2.1 | I101: =Data!J7 -> Yes | J101: =Data!K7 -> Phone
A102: =Data!A8 -> VG-1007 | B102: =Data!B8 -> 46247 | C102: =Data!D8 -> P3 | D102: =Data!E8 -> Closed | E102: =Data!F8 -> Access | F102: =Data!G8 -> P. Joshi | G102: =Data!H8 -> 24 | H102: =Data!I8 -> 25 | I102: =Data!J8 -> No | J102: =Data!K8 -> Phone
A103: =Data!A9 -> VG-1008 | B103: =Data!B9 -> 46209 | C103: =Data!D9 -> P1 | D103: =Data!E9 -> In Progress | E103: =Data!F9 -> Service Request | F103: =Data!G9 -> P. Joshi | G103: =Data!H9 -> 4 | H103: =Data!I9 -> 0 | I103: =Data!J9 -> Pending | J103: =Data!K9 -> Phone
...

Sheet Data
A1: Ticket ID | B1: Created Date | C1: Closed Date | D1: Priority | E1: Status | F1: Category | G1: Assigned To | H1: SLA Target (hrs) | I1: Resolution Time (hrs) | J1: SLA Met | K1: Channel
A2: VG-1001 | B2: 46077 | C2: 46078 | D2: P3 | E2: Closed | F2: Application Error | G2: S. Kumar | H2: 24 | I2: 25.4 | J2: No | K2: Phone
A3: VG-1002 | B3: 46153 | C3: 46153 | D3: P2 | E3: Closed | F3: Performance | G3: M. Singh | H3: 8 | I3: 8.8 | J3: No | K3: Phone
A4: VG-1003 | B4: 46226 | D4: P2 | E4: In Progress | F4: Access | G4: S. Kumar | H4: 8 | J4: Pending | K4: Email
A5: VG-1004 | B5: 46184 | D5: P2 | E5: In Progress | F5: Performance | G5: P. Joshi | H5: 8 | J5: Pending | K5: Email
A6: VG-1005 | B6: 46105 | C6: 46105 | D6: P3 | E6: Closed | F6: Access | G6: A. Sharma | H6: 24 | I6: 11.3 | J6: Yes | K6: Email
A7: VG-1006 | B7: 46195 | C7: 46195 | D7: P1 | E7: Closed | F7: Service Request | G7: M. Singh | H7: 4 | I7: 2.1 | J7: Yes | K7: Phone
A8: VG-1007 | B8: 46247 | C8: 46248 | D8: P3 | E8: Closed | F8: Access | G8: P. Joshi | H8: 24 | I8: 25 | J8: No | K8: Phone
A9: VG-1008 | B9: 46209 | D9: P1 | E9: In Progress | F9: Service Request | G9: P. Joshi | H9: 4 | J9: Pending | K9: Phone
A10: VG-1009 | B10: 46122 | C10: 46122 | D10: P2 | E10: Closed | F10: Performance | G10: P. Joshi | H10: 8 | I10: 3.6 | J10: Yes | K10: Portal
A11: VG-1010 | B11: 46075 | D11: P1 | E11: In Progress | F11: Access | G11: S. Kumar | H11: 4 | J11: Pending | K11: Portal
A12: VG-1011 | B12: 46083 | C12: 46083 | D12: P1 | E12: Closed | F12: Data Issue | G12: P. Joshi | H12: 4 | I12: 3.2 | J12: Yes | K12: Email
A13: VG-1012 | B13: 46240 | D13: P2 | E13: Open | F13: Application Error | G13: P. Joshi | H13: 8 | J13: Pending | K13: Portal
A14: VG-1013 | B14: 46256 | C14: 46256 | D14: P2 | E14: Closed | F14: Data Issue | G14: A. Sharma | H14: 8 | I14: 6.2 | J14: Yes | K14: Portal
A15: VG-1014 | B15: 46265 | C15: 46265 | D15: P2 | E15: Closed | F15: Service Request | G15: A. Sharma | H15: 8 | I15: 11.2 | J15: No | K15: Phone
A16: VG-1015 | B16: 46096 | C16: 46096 | D16: P2 | E16: Closed | F16: Access | G16: M. Singh | H16: 8 | I16: 7.7 | J16: Yes | K16: Portal
A17: VG-1016 | B17: 46033 | C17: 46033 | D17: P2 | E17: Closed | F17: Service Request | G17: S. Kumar | H17: 8 | I17: 5.3 | J17: Yes | K17: Portal
A18: VG-1017 | B18: 46177 | C18: 46178 | D18: P3 | E18: Closed | F18: Service Request | G18: S. Kumar | H18: 24 | I18: 24.5 | J18: No | K18: Email
A19: VG-1018 | B19: 46221 | C19: 46221 | D19: P1 | E19: Closed | F19: Access | G19: P. Joshi | H19: 4 | I19: 2.7 | J19: Yes | K19: Phone
A20: VG-1019 | B20: 46167 | D20: P3 | E20: Open | F20: Performance | G20: S. Kumar | H20: 24 | J20: Pending | K20: Email
A21: VG-1020 | B21: 46040 | D21: P1 | E21: In Progress | F21: Access | G21: R. Patel | H21: 4 | J21: Pending | K21: Portal
A22: VG-1021 | B22: 46279 | C22: 46279 | D22: P2 | E22: Closed | F22: Performance | G22: S. Kumar | H22: 8 | I22: 3.5 | J22: Yes | K22: Phone
A23: VG-1022 | B23: 46211 | C23: 46211 | D23: P1 | E23: Closed | F23: Application Error | G23: P. Joshi | H23: 4 | I23: 4.2 | J23: No | K23: Phone
A24: VG-1023 | B24: 46124 | C24: 46124 | D24: P2 | E24: Closed | F24: Service Request | G24: P. Joshi | H24: 8 | I24: 3.9 | J24: Yes | K24: Phone
A25: VG-1024 | B25: 46183 | D25: P2 | E25: Open | F25: Data Issue | G25: A. Sharma | H25: 8 | J25: Pending | K25: Email
A26: VG-1025 | B26: 46242 | D26: P2 | E26: In Progress | F26: Access | G26: S. Kumar | H26: 8 | J26: Pending | K26: Email
A27: VG-1026 | B27: 46089 | C27: 46089 | D27: P1 | E27: Closed | F27: Application Error | G27: S. Kumar | H27: 4 | I27: 6 | J27: No | K27: Portal
A28: VG-1027 | B28: 46252 | C28: 46252 | D28: P1 | E28: Closed | F28: Access | G28: S. Kumar | H28: 4 | I28: 3.1 | J28: Yes | K28: Phone
A29: VG-1028 | B29: 46211 | C29: 46211 | D29: P3 | E29: Closed | F29: Application Error | G29: A. Sharma | H29: 24 | I29: 5.8 | J29: Yes | K29: Email
A30: VG-1029 | B30: 46111 | C30: 46111 | D30: P1 | E30: Closed | F30: Performance | G30: P. Joshi | H30: 4 | I30: 5.9 | J30: No | K30: Phone
A31: VG-1030 | B31: 46308 | C31: 46308 | D31: P3 | E31: Closed | F31: Performance | G31: M. Singh | H31: 24 | I31: 16.2 | J31: Yes | K31: Portal
A32: VG-1031 | B32: 46062 | C32: 46062 | D32: P2 | E32: Closed | F32: Data Issue | G32: A. Sharma | H32: 8 | I32: 9 | J32: No | K32: Email
A33: VG-1032 | B33: 46241 | D33: P1 | E33: In Progress | F33: Application Error | G33: A. Sharma | H33: 4 | J33: Pending | K33: Email
A34: VG-1033 | B34: 46179 | C34: 46179 | D34: P1 | E34: Closed | F34: Data Issue | G34: R. Patel | H34: 4 | I34: 3 | J34: Yes | K34: Email
A35: VG-1034 | B35: 46253 | D35: P2 | E35: In Progress | F35: Service Request | G35: P. Joshi | H35: 8 | J35: Pending | K35: Email
A36: VG-1035 | B36: 46174 | D36: P1 | E36: Open | F36: Application Error | G36: S. Kumar | H36: 4 | J36: Pending | K36: Phone
A37: VG-1036 | B37: 46283 | C37: 46283 | D37: P1 | E37: Closed | F37: Access | G37: S. Kumar | H37: 4 | I37: 5.3 | J37: No | K37: Email
A38: VG-1037 | B38: 46086 | C38: 46086 | D38: P2 | E38: Closed | F38: Performance | G38: A. Sharma | H38: 8 | I38: 4.5 | J38: Yes | K38: Portal
A39: VG-1038 | B39: 46093 | D39: P2 | E39: Open | F39: Performance | G39: R. Patel | H39: 8 | J39: Pending | K39: Phone
A40: VG-1039 | B40: 46249 | D40: P1 | E40: Open | F40: Access | G40: M. Singh | H40: 4 | J40: Pending | K40: Portal
...
